Processing tasks in duration order (longest first):
+-----+-----------------------------+------------+------------+
|   # | Task Name                   | Duration   | Source     |
+=====+=============================+============+============+
|   1 | organization-json-generator | 3m 30s     | calculated |
+-----+-----------------------------+------------+------------+
Total tasks: 1
Starting harness run
Run ID: 2025-10-19_23-48-01_vmain
Running task: organization-json-generator
Harness execution failed for /home/claude/.cache/terminal-bench/terminal-bench-core/0.1.1/organization-json-generator: ("Error creating docker client: Error while fetching server API version: ('Connection aborted.', PermissionError(13, 'Permission denied'))", 'Please ensure that Docker is installed and running.')
Traceback (most recent call last):
  File "/home/claude/fireteam/benchmarks/terminal_bench/.venv/lib/python3.12/site-packages/urllib3/connectionpool.py", line 787, in urlopen
    response = self._make_request(
               ^^^^^^^^^^^^^^^^^^^
  File "/home/claude/fireteam/benchmarks/terminal_bench/.venv/lib/python3.12/site-packages/urllib3/connectionpool.py", line 493, in _make_request
    conn.request(
  File "/home/claude/fireteam/benchmarks/terminal_bench/.venv/lib/python3.12/site-packages/urllib3/connection.py", line 494, in request
    self.endheaders()
  File "/usr/lib/python3.12/http/client.py", line 1331, in endheaders
    self._send_output(message_body, encode_chunked=encode_chunked)
  File "/usr/lib/python3.12/http/client.py", line 1091, in _send_output
    self.send(msg)
  File "/usr/lib/python3.12/http/client.py", line 1035, in send
    self.connect()
  File "/home/claude/fireteam/benchmarks/terminal_bench/.venv/lib/python3.12/site-packages/docker/transport/unixconn.py", line 26, in connect
    sock.connect(self.unix_socket)
PermissionError: [Errno 13] Permission denied

During handling of the above exception, another exception occurred:

Traceback (most recent call last):
  File "/home/claude/fireteam/benchmarks/terminal_bench/.venv/lib/python3.12/site-packages/requests/adapters.py", line 644, in send
    resp = conn.urlopen(
           ^^^^^^^^^^^^^
  File "/home/claude/fireteam/benchmarks/terminal_bench/.venv/lib/python3.12/site-packages/urllib3/connectionpool.py", line 841, in urlopen
    retries = retries.increment(
              ^^^^^^^^^^^^^^^^^^
  File "/home/claude/fireteam/benchmarks/terminal_bench/.venv/lib/python3.12/site-packages/urllib3/util/retry.py", line 474, in increment
    raise reraise(type(error), error, _stacktrace)
          ^^^^^^^^^^^^^^^^^^^^^^^^^^^^^^^^^^^^^^^^
  File "/home/claude/fireteam/benchmarks/terminal_bench/.venv/lib/python3.12/site-packages/urllib3/util/util.py", line 38, in reraise
    raise value.with_traceback(tb)
  File "/home/claude/fireteam/benchmarks/terminal_bench/.venv/lib/python3.12/site-packages/urllib3/connectionpool.py", line 787, in urlopen
    response = self._make_request(
               ^^^^^^^^^^^^^^^^^^^
  File "/home/claude/fireteam/benchmarks/terminal_bench/.venv/lib/python3.12/site-packages/urllib3/connectionpool.py", line 493, in _make_request
    conn.request(
  File "/home/claude/fireteam/benchmarks/terminal_bench/.venv/lib/python3.12/site-packages/urllib3/connection.py", line 494, in request
    self.endheaders()
  File "/usr/lib/python3.12/http/client.py", line 1331, in endheaders
    self._send_output(message_body, encode_chunked=encode_chunked)
  File "/usr/lib/python3.12/http/client.py", line 1091, in _send_output
    self.send(msg)
  File "/usr/lib/python3.12/http/client.py", line 1035, in send
    self.connect()
  File "/home/claude/fireteam/benchmarks/terminal_bench/.venv/lib/python3.12/site-packages/docker/transport/unixconn.py", line 26, in connect
    sock.connect(self.unix_socket)
urllib3.exceptions.ProtocolError: ('Connection aborted.', PermissionError(13, 'Permission denied'))

During handling of the above exception, another exception occurred:

Traceback (most recent call last):
  File "/home/claude/fireteam/benchmarks/terminal_bench/.venv/lib/python3.12/site-packages/docker/api/client.py", line 223, in _retrieve_server_version
    return self.version(api_version=False)["ApiVersion"]
           ^^^^^^^^^^^^^^^^^^^^^^^^^^^^^^^
  File "/home/claude/fireteam/benchmarks/terminal_bench/.venv/lib/python3.12/site-packages/docker/api/daemon.py", line 181, in version
    return self._result(self._get(url), json=True)
                        ^^^^^^^^^^^^^^
  File "/home/claude/fireteam/benchmarks/terminal_bench/.venv/lib/python3.12/site-packages/docker/utils/decorators.py", line 44, in inner
    return f(self, *args, **kwargs)
           ^^^^^^^^^^^^^^^^^^^^^^^^
  File "/home/claude/fireteam/benchmarks/terminal_bench/.venv/lib/python3.12/site-packages/docker/api/client.py", line 246, in _get
    return self.get(url, **self._set_request_timeout(kwargs))
           ^^^^^^^^^^^^^^^^^^^^^^^^^^^^^^^^^^^^^^^^^^^^^^^^^^
  File "/home/claude/fireteam/benchmarks/terminal_bench/.venv/lib/python3.12/site-packages/requests/sessions.py", line 602, in get
    return self.request("GET", url, **kwargs)
           ^^^^^^^^^^^^^^^^^^^^^^^^^^^^^^^^^^
  File "/home/claude/fireteam/benchmarks/terminal_bench/.venv/lib/python3.12/site-packages/requests/sessions.py", line 589, in request
    resp = self.send(prep, **send_kwargs)
           ^^^^^^^^^^^^^^^^^^^^^^^^^^^^^^
  File "/home/claude/fireteam/benchmarks/terminal_bench/.venv/lib/python3.12/site-packages/requests/sessions.py", line 703, in send
    r = adapter.send(request, **kwargs)
        ^^^^^^^^^^^^^^^^^^^^^^^^^^^^^^^
  File "/home/claude/fireteam/benchmarks/terminal_bench/.venv/lib/python3.12/site-packages/requests/adapters.py", line 659, in send
    raise ConnectionError(err, request=request)
requests.exceptions.ConnectionError: ('Connection aborted.', PermissionError(13, 'Permission denied'))

The above exception was the direct cause of the following exception:

Traceback (most recent call last):
  File "/home/claude/fireteam/benchmarks/terminal_bench/.venv/lib/python3.12/site-packages/terminal_bench/terminal/docker_compose_manager.py", line 44, in __init__
    self._client = docker.from_env()
                   ^^^^^^^^^^^^^^^^^
  File "/home/claude/fireteam/benchmarks/terminal_bench/.venv/lib/python3.12/site-packages/docker/client.py", line 94, in from_env
    return cls(
           ^^^^
  File "/home/claude/fireteam/benchmarks/terminal_bench/.venv/lib/python3.12/site-packages/docker/client.py", line 45, in __init__
    self.api = APIClient(*args, **kwargs)
               ^^^^^^^^^^^^^^^^^^^^^^^^^^
  File "/home/claude/fireteam/benchmarks/terminal_bench/.venv/lib/python3.12/site-packages/docker/api/client.py", line 207, in __init__
    self._version = self._retrieve_server_version()
                    ^^^^^^^^^^^^^^^^^^^^^^^^^^^^^^^
  File "/home/claude/fireteam/benchmarks/terminal_bench/.venv/lib/python3.12/site-packages/docker/api/client.py", line 230, in _retrieve_server_version
    raise DockerException(
docker.errors.DockerException: Error while fetching server API version: ('Connection aborted.', PermissionError(13, 'Permission denied'))

During handling of the above exception, another exception occurred:

Traceback (most recent call last):
  File "/home/claude/fireteam/benchmarks/terminal_bench/.venv/lib/python3.12/site-packages/terminal_bench/harness/harness.py", line 1011, in _execute_single_trial
    trial_results = self._run_trial(trial_handler)
                    ^^^^^^^^^^^^^^^^^^^^^^^^^^^^^^
  File "/home/claude/fireteam/benchmarks/terminal_bench/.venv/lib/python3.12/site-packages/terminal_bench/harness/harness.py", line 717, in _run_trial
    with spin_up_terminal(
  File "/usr/lib/python3.12/contextlib.py", line 137, in __enter__
    return next(self.gen)
           ^^^^^^^^^^^^^^
  File "/home/claude/fireteam/benchmarks/terminal_bench/.venv/lib/python3.12/site-packages/terminal_bench/terminal/terminal.py", line 161, in spin_up_terminal
    terminal = Terminal(
               ^^^^^^^^^
  File "/home/claude/fireteam/benchmarks/terminal_bench/.venv/lib/python3.12/site-packages/terminal_bench/terminal/terminal.py", line 38, in __init__
    self._compose_manager = DockerComposeManager(
                            ^^^^^^^^^^^^^^^^^^^^^
  File "/home/claude/fireteam/benchmarks/terminal_bench/.venv/lib/python3.12/site-packages/terminal_bench/terminal/docker_compose_manager.py", line 46, in __init__
    raise RuntimeError(
RuntimeError: ("Error creating docker client: Error while fetching server API version: ('Connection aborted.', PermissionError(13, 'Permission denied'))", 'Please ensure that Docker is installed and running.')
